Traceback (most recent call last):
  File "/shared/home/pfrancois/.local/lib/python3.9/site-packages/jupyter_cache/executors/utils.py", line 58, in single_nb_execution
    executenb(
  File "/shared/ifbstor1/software/jupyterhub/lib/python3.9/site-packages/nbclient/client.py", line 1117, in execute
    return NotebookClient(nb=nb, resources=resources, km=km, **kwargs).execute()
  File "/shared/ifbstor1/software/jupyterhub/lib/python3.9/site-packages/nbclient/util.py", line 78, in wrapped
    return just_run(coro(*args, **kwargs))
  File "/shared/ifbstor1/software/jupyterhub/lib/python3.9/site-packages/nbclient/util.py", line 57, in just_run
    return loop.run_until_complete(coro)
  File "/shared/ifbstor1/software/jupyterhub/lib/python3.9/asyncio/base_events.py", line 642, in run_until_complete
    return future.result()
  File "/shared/ifbstor1/software/jupyterhub/lib/python3.9/site-packages/nbclient/client.py", line 558, in async_execute
    await self.async_execute_cell(
  File "/shared/ifbstor1/software/jupyterhub/lib/python3.9/site-packages/nbclient/client.py", line 862, in async_execute_cell
    self._check_raise_for_error(cell, exec_reply)
  File "/shared/ifbstor1/software/jupyterhub/lib/python3.9/site-packages/nbclient/client.py", line 765, in _check_raise_for_error
    raise CellExecutionError.from_cell_and_msg(cell, exec_reply_content)
nbclient.exceptions.CellExecutionError: An error occurred while executing the following cell:
------------------
# Afficher la liste des environnements disponibles
module avail -l | head
------------------


: 1

